2018-03-03 20:08:03 ERROR (MainThread) [homeassistant.core] Timer got out of sync. Resetting
2018-03-03 20:08:15 ERROR (MainThread) [homeassistant.components.sensor] Error while setting up platform sabnzbd
Traceback (most recent call last):
  File "/usr/lib/python3.6/site-packages/homeassistant/helpers/entity_platform.py", line 84, in async_setup
    SLOW_SETUP_MAX_WAIT, loop=hass.loop)
  File "/usr/lib/python3.6/asyncio/tasks.py", line 358, in wait_for
    return fut.result()
  File "/usr/lib/python3.6/asyncio/futures.py", line 245, in result
    raise self._exception
  File "/usr/lib/python3.6/asyncio/tasks.py", line 180, in _step
    result = coro.send(None)
  File "/usr/lib/python3.6/site-packages/homeassistant/components/sensor/sabnzbd.py", line 153, in async_setup_platform
    if not (yield from async_check_sabnzbd(SabnzbdApi, base_url, api_key)):
  File "/usr/lib/python3.6/site-packages/homeassistant/components/sensor/sabnzbd.py", line 62, in async_check_sabnzbd
    yield from sab_api.check_available()
  File "/usr/lib/python3.6/site-packages/pysabnzbd/__init__.py", line 44, in check_available
    resp = yield from session.get(url, params=api_args)
  File "/usr/lib/python3.6/site-packages/aiohttp/helpers.py", line 104, in __iter__
    ret = yield from self._coro
  File "/usr/lib/python3.6/site-packages/aiohttp/client.py", line 262, in _request
    ssl_context=ssl_context, proxy_headers=proxy_headers)
  File "/usr/lib/python3.6/site-packages/aiohttp/client_reqrep.py", line 105, in __init__
    url2 = url.with_query(params)
  File "/usr/lib/python3.6/site-packages/yarl/__init__.py", line 848, in with_query
    new_query = self._get_str_query(*args, **kwargs)
  File "/usr/lib/python3.6/site-packages/yarl/__init__.py", line 816, in _get_str_query
    "should be str or int, got {!r}".format(v))
TypeError: Invalid variable type: mapping value should be str or int, got None
